<?xml version="1.0" ?>
<robot name="irb4600_workspace" xmlns:xacro="http://ros.org/wiki/xacro">
  <!-- Includes -->
  <xacro:include filename="$(find abb_irb4600_support)/urdf/irb4600_60_205_macro.xacro"/> <!-- Robot Arm -->
  <xacro:include filename="$(find workcell1_support)/urdf/sander.xacro"/> <!-- Sanding Tool -->

  <!-- Constants  -->

  <!-- Components -->
  <xacro:abb_irb4600_60_205 prefix=""/>
  <xacro:sander prefix="sander_"/>

  <!-- Links -->
  <link name="world_frame"/>

  <link name="rail_origin"/>

  <link name="rail_y_carriage"/>

  <link name="rail_robot_carriage"/>

  <!-- Joints -->
  <joint name="robot_to_sander" type="fixed"> <!-- Connects robot & tool -->
    <parent link="tool0"/>
    <child link="sander_base_link"/>
    <origin xyz="0 0 0" rpy="0 0 0"/>
  </joint>

  <joint name="world_to_rail" type="fixed">
    <parent link="world_frame"/>
    <child link="rail_origin"/>
    <origin xyz="0 0 2.75" rpy="0 0 0"/>
  </joint>

  <joint name="rail_x" type="prismatic">
    <parent link="rail_origin"/>
    <child link="rail_y_carriage"/>
    <origin xyz="0 0 0" rpy="0 0 0"/>
    <axis xyz="1 0 0"/>
    <limit lower="-2" upper="2" effort="0" velocity="1.0"/>
  </joint>

  <joint name="rail_y" type="prismatic">
    <parent link="rail_y_carriage"/>
    <child link="rail_robot_carriage"/>
    <origin xyz="0 0 0" rpy="0 0 0"/>
    <axis xyz="0 1 0"/>
    <limit lower="-2" upper="2" effort="0" velocity="1.0"/>
  </joint>

  <joint name="carriage_to_robot" type="fixed">
    <parent link="rail_robot_carriage"/>
    <child link="base_link"/>
    <origin xyz="0 0 0" rpy="${pi} 0 0"/>
  </joint>

</robot>
